2016-08-25 12:28:26,966 [Thread-2:6256] [django.request:256] [base:handle_uncaught_exception] [ERROR]- Internal Server Error: /
Traceback (most recent call last):
  File "C:\Python27\lib\site-packages\django\core\handlers\base.py", line 119, in get_response
    resolver_match = resolver.resolve(request.path_info)
  File "C:\Python27\lib\site-packages\django\core\urlresolvers.py", line 366, in resolve
    for pattern in self.url_patterns:
  File "C:\Python27\lib\site-packages\django\core\urlresolvers.py", line 402, in url_patterns
    patterns = getattr(self.urlconf_module, "urlpatterns", self.urlconf_module)
  File "C:\Python27\lib\site-packages\django\core\urlresolvers.py", line 396, in urlconf_module
    self._urlconf_module = import_module(self.urlconf_name)
  File "C:\Python27\Lib\importlib\__init__.py", line 37, in import_module
    __import__(name)
  File "C:\Users\Administrator\PycharmProjects\blog\blog\urls.py", line 3, in <module>
    from myblog import views
  File "C:\Users\Administrator\PycharmProjects\blog\myblog\views.py", line 14
    'SITE_NAME' : settings.SITE_NAME
              ^
SyntaxError: invalid syntax
2016-08-25 12:29:04,188 [Thread-3:10548] [django.request:256] [base:handle_uncaught_exception] [ERROR]- Internal Server Error: /
Traceback (most recent call last):
  File "C:\Python27\lib\site-packages\django\core\handlers\base.py", line 119, in get_response
    resolver_match = resolver.resolve(request.path_info)
  File "C:\Python27\lib\site-packages\django\core\urlresolvers.py", line 366, in resolve
    for pattern in self.url_patterns:
  File "C:\Python27\lib\site-packages\django\core\urlresolvers.py", line 402, in url_patterns
    patterns = getattr(self.urlconf_module, "urlpatterns", self.urlconf_module)
  File "C:\Python27\lib\site-packages\django\core\urlresolvers.py", line 396, in urlconf_module
    self._urlconf_module = import_module(self.urlconf_name)
  File "C:\Python27\Lib\importlib\__init__.py", line 37, in import_module
    __import__(name)
  File "C:\Users\Administrator\PycharmProjects\blog\blog\urls.py", line 3, in <module>
    from myblog import views
  File "C:\Users\Administrator\PycharmProjects\blog\myblog\views.py", line 14
    'SITE_NAME':settings.SITE_NAME
              ^
SyntaxError: invalid syntax
2016-08-25 12:29:18,536 [Thread-4:11256] [django.request:256] [base:handle_uncaught_exception] [ERROR]- Internal Server Error: /
Traceback (most recent call last):
  File "C:\Python27\lib\site-packages\django\core\handlers\base.py", line 119, in get_response
    resolver_match = resolver.resolve(request.path_info)
  File "C:\Python27\lib\site-packages\django\core\urlresolvers.py", line 366, in resolve
    for pattern in self.url_patterns:
  File "C:\Python27\lib\site-packages\django\core\urlresolvers.py", line 402, in url_patterns
    patterns = getattr(self.urlconf_module, "urlpatterns", self.urlconf_module)
  File "C:\Python27\lib\site-packages\django\core\urlresolvers.py", line 396, in urlconf_module
    self._urlconf_module = import_module(self.urlconf_name)
  File "C:\Python27\Lib\importlib\__init__.py", line 37, in import_module
    __import__(name)
  File "C:\Users\Administrator\PycharmProjects\blog\blog\urls.py", line 3, in <module>
    from myblog import views
  File "C:\Users\Administrator\PycharmProjects\blog\myblog\views.py", line 14
    'SITE_NAME':settings.SITE_NAME
              ^
SyntaxError: invalid syntax
2016-08-25 12:30:52,088 [Thread-5:10772] [django.request:256] [base:handle_uncaught_exception] [ERROR]- Internal Server Error: /
Traceback (most recent call last):
  File "C:\Python27\lib\site-packages\django\core\handlers\base.py", line 119, in get_response
    resolver_match = resolver.resolve(request.path_info)
  File "C:\Python27\lib\site-packages\django\core\urlresolvers.py", line 366, in resolve
    for pattern in self.url_patterns:
  File "C:\Python27\lib\site-packages\django\core\urlresolvers.py", line 402, in url_patterns
    patterns = getattr(self.urlconf_module, "urlpatterns", self.urlconf_module)
  File "C:\Python27\lib\site-packages\django\core\urlresolvers.py", line 396, in urlconf_module
    self._urlconf_module = import_module(self.urlconf_name)
  File "C:\Python27\Lib\importlib\__init__.py", line 37, in import_module
    __import__(name)
  File "C:\Users\Administrator\PycharmProjects\blog\blog\urls.py", line 3, in <module>
    from myblog import views
  File "C:\Users\Administrator\PycharmProjects\blog\myblog\views.py", line 13
    'SITE_NAME':settings.SITE_NAME
              ^
SyntaxError: invalid syntax
2016-08-25 12:31:57,956 [Thread-7:10144] [django.request:256] [base:handle_uncaught_exception] [ERROR]- Internal Server Error: /
Traceback (most recent call last):
  File "C:\Python27\lib\site-packages\django\core\handlers\base.py", line 119, in get_response
    resolver_match = resolver.resolve(request.path_info)
  File "C:\Python27\lib\site-packages\django\core\urlresolvers.py", line 366, in resolve
    for pattern in self.url_patterns:
  File "C:\Python27\lib\site-packages\django\core\urlresolvers.py", line 402, in url_patterns
    patterns = getattr(self.urlconf_module, "urlpatterns", self.urlconf_module)
  File "C:\Python27\lib\site-packages\django\core\urlresolvers.py", line 396, in urlconf_module
    self._urlconf_module = import_module(self.urlconf_name)
  File "C:\Python27\Lib\importlib\__init__.py", line 37, in import_module
    __import__(name)
  File "C:\Users\Administrator\PycharmProjects\blog\blog\urls.py", line 3, in <module>
    from myblog import views
  File "C:\Users\Administrator\PycharmProjects\blog\myblog\views.py", line 13
    'SITE_NAME':settings.SITE_NAME
              ^
SyntaxError: invalid syntax
2016-08-25 12:32:25,882 [Thread-8:8288] [django.request:256] [base:handle_uncaught_exception] [ERROR]- Internal Server Error: /
Traceback (most recent call last):
  File "C:\Python27\lib\site-packages\django\core\handlers\base.py", line 119, in get_response
    resolver_match = resolver.resolve(request.path_info)
  File "C:\Python27\lib\site-packages\django\core\urlresolvers.py", line 366, in resolve
    for pattern in self.url_patterns:
  File "C:\Python27\lib\site-packages\django\core\urlresolvers.py", line 402, in url_patterns
    patterns = getattr(self.urlconf_module, "urlpatterns", self.urlconf_module)
  File "C:\Python27\lib\site-packages\django\core\urlresolvers.py", line 396, in urlconf_module
    self._urlconf_module = import_module(self.urlconf_name)
  File "C:\Python27\Lib\importlib\__init__.py", line 37, in import_module
    __import__(name)
  File "C:\Users\Administrator\PycharmProjects\blog\blog\urls.py", line 3, in <module>
    from myblog import views
  File "C:\Users\Administrator\PycharmProjects\blog\myblog\views.py", line 13
    'SITE_NAME':settings.SITE_NAME
              ^
SyntaxError: invalid syntax
2016-08-25 12:32:30,403 [Thread-9:4788] [django.request:256] [base:handle_uncaught_exception] [ERROR]- Internal Server Error: /
Traceback (most recent call last):
  File "C:\Python27\lib\site-packages\django\core\handlers\base.py", line 119, in get_response
    resolver_match = resolver.resolve(request.path_info)
  File "C:\Python27\lib\site-packages\django\core\urlresolvers.py", line 366, in resolve
    for pattern in self.url_patterns:
  File "C:\Python27\lib\site-packages\django\core\urlresolvers.py", line 402, in url_patterns
    patterns = getattr(self.urlconf_module, "urlpatterns", self.urlconf_module)
  File "C:\Python27\lib\site-packages\django\core\urlresolvers.py", line 396, in urlconf_module
    self._urlconf_module = import_module(self.urlconf_name)
  File "C:\Python27\Lib\importlib\__init__.py", line 37, in import_module
    __import__(name)
  File "C:\Users\Administrator\PycharmProjects\blog\blog\urls.py", line 3, in <module>
    from myblog import views
  File "C:\Users\Administrator\PycharmProjects\blog\myblog\views.py", line 13
    'SITE_NAME':settings.SITE_NAME
              ^
SyntaxError: invalid syntax
2016-08-25 12:32:42,323 [Thread-10:3592] [django.request:256] [base:handle_uncaught_exception] [ERROR]- Internal Server Error: /
Traceback (most recent call last):
  File "C:\Python27\lib\site-packages\django\core\handlers\base.py", line 119, in get_response
    resolver_match = resolver.resolve(request.path_info)
  File "C:\Python27\lib\site-packages\django\core\urlresolvers.py", line 366, in resolve
    for pattern in self.url_patterns:
  File "C:\Python27\lib\site-packages\django\core\urlresolvers.py", line 402, in url_patterns
    patterns = getattr(self.urlconf_module, "urlpatterns", self.urlconf_module)
  File "C:\Python27\lib\site-packages\django\core\urlresolvers.py", line 396, in urlconf_module
    self._urlconf_module = import_module(self.urlconf_name)
  File "C:\Python27\Lib\importlib\__init__.py", line 37, in import_module
    __import__(name)
  File "C:\Users\Administrator\PycharmProjects\blog\blog\urls.py", line 3, in <module>
    from myblog import views
  File "C:\Users\Administrator\PycharmProjects\blog\myblog\views.py", line 13
    'SITE_NAME':settings.SITE_NAME
              ^
SyntaxError: invalid syntax
2016-08-25 12:32:45,789 [Thread-11:1808] [django.request:256] [base:handle_uncaught_exception] [ERROR]- Internal Server Error: /
Traceback (most recent call last):
  File "C:\Python27\lib\site-packages\django\core\handlers\base.py", line 119, in get_response
    resolver_match = resolver.resolve(request.path_info)
  File "C:\Python27\lib\site-packages\django\core\urlresolvers.py", line 366, in resolve
    for pattern in self.url_patterns:
  File "C:\Python27\lib\site-packages\django\core\urlresolvers.py", line 402, in url_patterns
    patterns = getattr(self.urlconf_module, "urlpatterns", self.urlconf_module)
  File "C:\Python27\lib\site-packages\django\core\urlresolvers.py", line 396, in urlconf_module
    self._urlconf_module = import_module(self.urlconf_name)
  File "C:\Python27\Lib\importlib\__init__.py", line 37, in import_module
    __import__(name)
  File "C:\Users\Administrator\PycharmProjects\blog\blog\urls.py", line 3, in <module>
    from myblog import views
  File "C:\Users\Administrator\PycharmProjects\blog\myblog\views.py", line 13
    'SITE_NAME':settings.SITE_NAME
              ^
SyntaxError: invalid syntax
2016-08-25 12:33:20,253 [Thread-12:7736] [django.request:256] [base:handle_uncaught_exception] [ERROR]- Internal Server Error: /
Traceback (most recent call last):
  File "C:\Python27\lib\site-packages\django\core\handlers\base.py", line 119, in get_response
    resolver_match = resolver.resolve(request.path_info)
  File "C:\Python27\lib\site-packages\django\core\urlresolvers.py", line 366, in resolve
    for pattern in self.url_patterns:
  File "C:\Python27\lib\site-packages\django\core\urlresolvers.py", line 402, in url_patterns
    patterns = getattr(self.urlconf_module, "urlpatterns", self.urlconf_module)
  File "C:\Python27\lib\site-packages\django\core\urlresolvers.py", line 396, in urlconf_module
    self._urlconf_module = import_module(self.urlconf_name)
  File "C:\Python27\Lib\importlib\__init__.py", line 37, in import_module
    __import__(name)
  File "C:\Users\Administrator\PycharmProjects\blog\blog\urls.py", line 3, in <module>
    from myblog import views
  File "C:\Users\Administrator\PycharmProjects\blog\myblog\views.py", line 13
    'SITE_DESC':settings.SITE_DESC
              ^
SyntaxError: invalid syntax
2016-08-25 12:33:22,832 [Thread-13:9756] [django.request:256] [base:handle_uncaught_exception] [ERROR]- Internal Server Error: /
Traceback (most recent call last):
  File "C:\Python27\lib\site-packages\django\core\handlers\base.py", line 119, in get_response
    resolver_match = resolver.resolve(request.path_info)
  File "C:\Python27\lib\site-packages\django\core\urlresolvers.py", line 366, in resolve
    for pattern in self.url_patterns:
  File "C:\Python27\lib\site-packages\django\core\urlresolvers.py", line 402, in url_patterns
    patterns = getattr(self.urlconf_module, "urlpatterns", self.urlconf_module)
  File "C:\Python27\lib\site-packages\django\core\urlresolvers.py", line 396, in urlconf_module
    self._urlconf_module = import_module(self.urlconf_name)
  File "C:\Python27\Lib\importlib\__init__.py", line 37, in import_module
    __import__(name)
  File "C:\Users\Administrator\PycharmProjects\blog\blog\urls.py", line 3, in <module>
    from myblog import views
  File "C:\Users\Administrator\PycharmProjects\blog\myblog\views.py", line 13
    'SITE_DESC':settings.SITE_DESC
              ^
SyntaxError: invalid syntax
2016-08-25 12:33:27,357 [Thread-14:3304] [django.request:256] [base:handle_uncaught_exception] [ERROR]- Internal Server Error: /
Traceback (most recent call last):
  File "C:\Python27\lib\site-packages\django\core\handlers\base.py", line 119, in get_response
    resolver_match = resolver.resolve(request.path_info)
  File "C:\Python27\lib\site-packages\django\core\urlresolvers.py", line 366, in resolve
    for pattern in self.url_patterns:
  File "C:\Python27\lib\site-packages\django\core\urlresolvers.py", line 402, in url_patterns
    patterns = getattr(self.urlconf_module, "urlpatterns", self.urlconf_module)
  File "C:\Python27\lib\site-packages\django\core\urlresolvers.py", line 396, in urlconf_module
    self._urlconf_module = import_module(self.urlconf_name)
  File "C:\Python27\Lib\importlib\__init__.py", line 37, in import_module
    __import__(name)
  File "C:\Users\Administrator\PycharmProjects\blog\blog\urls.py", line 3, in <module>
    from myblog import views
  File "C:\Users\Administrator\PycharmProjects\blog\myblog\views.py", line 13
    'SITE_DESC':settings.SITE_DESC
              ^
SyntaxError: invalid syntax
2016-08-25 12:33:28,786 [Thread-15:2080] [django.request:256] [base:handle_uncaught_exception] [ERROR]- Internal Server Error: /
Traceback (most recent call last):
  File "C:\Python27\lib\site-packages\django\core\handlers\base.py", line 119, in get_response
    resolver_match = resolver.resolve(request.path_info)
  File "C:\Python27\lib\site-packages\django\core\urlresolvers.py", line 366, in resolve
    for pattern in self.url_patterns:
  File "C:\Python27\lib\site-packages\django\core\urlresolvers.py", line 402, in url_patterns
    patterns = getattr(self.urlconf_module, "urlpatterns", self.urlconf_module)
  File "C:\Python27\lib\site-packages\django\core\urlresolvers.py", line 396, in urlconf_module
    self._urlconf_module = import_module(self.urlconf_name)
  File "C:\Python27\Lib\importlib\__init__.py", line 37, in import_module
    __import__(name)
  File "C:\Users\Administrator\PycharmProjects\blog\blog\urls.py", line 3, in <module>
    from myblog import views
  File "C:\Users\Administrator\PycharmProjects\blog\myblog\views.py", line 13
    'SITE_DESC':settings.SITE_DESC
              ^
SyntaxError: invalid syntax
2016-08-25 12:33:41,164 [Thread-2:8352] [django.request:256] [base:handle_uncaught_exception] [ERROR]- Internal Server Error: /
Traceback (most recent call last):
  File "C:\Python27\lib\site-packages\django\core\handlers\base.py", line 119, in get_response
    resolver_match = resolver.resolve(request.path_info)
  File "C:\Python27\lib\site-packages\django\core\urlresolvers.py", line 366, in resolve
    for pattern in self.url_patterns:
  File "C:\Python27\lib\site-packages\django\core\urlresolvers.py", line 402, in url_patterns
    patterns = getattr(self.urlconf_module, "urlpatterns", self.urlconf_module)
  File "C:\Python27\lib\site-packages\django\core\urlresolvers.py", line 396, in urlconf_module
    self._urlconf_module = import_module(self.urlconf_name)
  File "C:\Python27\Lib\importlib\__init__.py", line 37, in import_module
    __import__(name)
  File "C:\Users\Administrator\PycharmProjects\blog\blog\urls.py", line 3, in <module>
    from myblog import views
  File "C:\Users\Administrator\PycharmProjects\blog\myblog\views.py", line 13
    'SITE_DESC':settings.SITE_DESC
              ^
SyntaxError: invalid syntax
2016-08-25 12:34:52,760 [Thread-2:7852] [django.request:256] [base:handle_uncaught_exception] [ERROR]- Internal Server Error: /
Traceback (most recent call last):
  File "C:\Python27\lib\site-packages\django\core\handlers\base.py", line 119, in get_response
    resolver_match = resolver.resolve(request.path_info)
  File "C:\Python27\lib\site-packages\django\core\urlresolvers.py", line 366, in resolve
    for pattern in self.url_patterns:
  File "C:\Python27\lib\site-packages\django\core\urlresolvers.py", line 402, in url_patterns
    patterns = getattr(self.urlconf_module, "urlpatterns", self.urlconf_module)
  File "C:\Python27\lib\site-packages\django\core\urlresolvers.py", line 396, in urlconf_module
    self._urlconf_module = import_module(self.urlconf_name)
  File "C:\Python27\Lib\importlib\__init__.py", line 37, in import_module
    __import__(name)
  File "C:\Users\Administrator\PycharmProjects\blog\blog\urls.py", line 3, in <module>
    from myblog import views
  File "C:\Users\Administrator\PycharmProjects\blog\myblog\views.py", line 12
    'SITE_DESC':settings.SITE_DESC
              ^
SyntaxError: invalid syntax
2016-08-25 12:36:25,619 [Thread-3:8720] [django.request:256] [base:handle_uncaught_exception] [ERROR]- Internal Server Error: /
Traceback (most recent call last):
  File "C:\Python27\lib\site-packages\django\core\handlers\base.py", line 119, in get_response
    resolver_match = resolver.resolve(request.path_info)
  File "C:\Python27\lib\site-packages\django\core\urlresolvers.py", line 366, in resolve
    for pattern in self.url_patterns:
  File "C:\Python27\lib\site-packages\django\core\urlresolvers.py", line 402, in url_patterns
    patterns = getattr(self.urlconf_module, "urlpatterns", self.urlconf_module)
  File "C:\Python27\lib\site-packages\django\core\urlresolvers.py", line 396, in urlconf_module
    self._urlconf_module = import_module(self.urlconf_name)
  File "C:\Python27\Lib\importlib\__init__.py", line 37, in import_module
    __import__(name)
  File "C:\Users\Administrator\PycharmProjects\blog\blog\urls.py", line 3, in <module>
    from myblog import views
  File "C:\Users\Administrator\PycharmProjects\blog\myblog\views.py", line 13
    'WEIBO_TENCENT':settings.WEIBO_TENCENT
                  ^
SyntaxError: invalid syntax
2016-08-25 12:38:04,325 [Thread-4:6616] [django.request:256] [base:handle_uncaught_exception] [ERROR]- Internal Server Error: /
Traceback (most recent call last):
  File "C:\Python27\lib\site-packages\django\core\handlers\base.py", line 119, in get_response
    resolver_match = resolver.resolve(request.path_info)
  File "C:\Python27\lib\site-packages\django\core\urlresolvers.py", line 366, in resolve
    for pattern in self.url_patterns:
  File "C:\Python27\lib\site-packages\django\core\urlresolvers.py", line 402, in url_patterns
    patterns = getattr(self.urlconf_module, "urlpatterns", self.urlconf_module)
  File "C:\Python27\lib\site-packages\django\core\urlresolvers.py", line 396, in urlconf_module
    self._urlconf_module = import_module(self.urlconf_name)
  File "C:\Python27\Lib\importlib\__init__.py", line 37, in import_module
    __import__(name)
  File "C:\Users\Administrator\PycharmProjects\blog\blog\urls.py", line 3, in <module>
    from myblog import views
  File "C:\Users\Administrator\PycharmProjects\blog\myblog\views.py", line 11
    'SITE_DESC':settings.SITE_DESC
              ^
SyntaxError: invalid syntax
2016-08-25 12:40:46,857 [Thread-2:2020] [django.request:256] [base:handle_uncaught_exception] [ERROR]- Internal Server Error: /
Traceback (most recent call last):
  File "C:\Python27\lib\site-packages\django\core\handlers\base.py", line 119, in get_response
    resolver_match = resolver.resolve(request.path_info)
  File "C:\Python27\lib\site-packages\django\core\urlresolvers.py", line 366, in resolve
    for pattern in self.url_patterns:
  File "C:\Python27\lib\site-packages\django\core\urlresolvers.py", line 402, in url_patterns
    patterns = getattr(self.urlconf_module, "urlpatterns", self.urlconf_module)
  File "C:\Python27\lib\site-packages\django\core\urlresolvers.py", line 396, in urlconf_module
    self._urlconf_module = import_module(self.urlconf_name)
  File "C:\Python27\Lib\importlib\__init__.py", line 37, in import_module
    __import__(name)
  File "C:\Users\Administrator\PycharmProjects\blog\blog\urls.py", line 3, in <module>
    from myblog import views
  File "C:\Users\Administrator\PycharmProjects\blog\myblog\views.py", line 26
    return render(request, 'base.html','category_list':category_list)
                                                      ^
SyntaxError: invalid syntax
2016-08-25 12:41:52,713 [Thread-3:8884] [django.request:256] [base:handle_uncaught_exception] [ERROR]- Internal Server Error: /
Traceback (most recent call last):
  File "C:\Python27\lib\site-packages\django\core\handlers\base.py", line 119, in get_response
    resolver_match = resolver.resolve(request.path_info)
  File "C:\Python27\lib\site-packages\django\core\urlresolvers.py", line 366, in resolve
    for pattern in self.url_patterns:
  File "C:\Python27\lib\site-packages\django\core\urlresolvers.py", line 402, in url_patterns
    patterns = getattr(self.urlconf_module, "urlpatterns", self.urlconf_module)
  File "C:\Python27\lib\site-packages\django\core\urlresolvers.py", line 396, in urlconf_module
    self._urlconf_module = import_module(self.urlconf_name)
  File "C:\Python27\Lib\importlib\__init__.py", line 37, in import_module
    __import__(name)
  File "C:\Users\Administrator\PycharmProjects\blog\blog\urls.py", line 3, in <module>
    from myblog import views
  File "C:\Users\Administrator\PycharmProjects\blog\myblog\views.py", line 27
    return render(request, 'base.html','category_list':category_list)
                                                      ^
SyntaxError: invalid syntax
2016-08-25 12:44:05,888 [Thread-4:9696] [django.request:256] [base:handle_uncaught_exception] [ERROR]- Internal Server Error: /
Traceback (most recent call last):
  File "C:\Python27\lib\site-packages\django\core\handlers\base.py", line 119, in get_response
    resolver_match = resolver.resolve(request.path_info)
  File "C:\Python27\lib\site-packages\django\core\urlresolvers.py", line 366, in resolve
    for pattern in self.url_patterns:
  File "C:\Python27\lib\site-packages\django\core\urlresolvers.py", line 402, in url_patterns
    patterns = getattr(self.urlconf_module, "urlpatterns", self.urlconf_module)
  File "C:\Python27\lib\site-packages\django\core\urlresolvers.py", line 396, in urlconf_module
    self._urlconf_module = import_module(self.urlconf_name)
  File "C:\Python27\Lib\importlib\__init__.py", line 37, in import_module
    __import__(name)
  File "C:\Users\Administrator\PycharmProjects\blog\blog\urls.py", line 3, in <module>
    from myblog import views
  File "C:\Users\Administrator\PycharmProjects\blog\myblog\views.py", line 27
    return render(request, 'base.html','category_list':category_list)
                                                      ^
SyntaxError: invalid syntax
2016-08-25 12:55:04,161 [Thread-2:10896] [django.request:256] [base:handle_uncaught_exception] [ERROR]- Internal Server Error: /
Traceback (most recent call last):
  File "C:\Python27\lib\site-packages\django\core\handlers\base.py", line 132, in get_response
    response = wrapped_callback(request, *callback_args, **callback_kwargs)
  File "C:\Users\Administrator\PycharmProjects\blog\myblog\views.py", line 27, in index
    return render(request, 'base.html',{'category_list':category_list})
UnboundLocalError: local variable 'category_list' referenced before assignment
2016-08-25 12:55:23,671 [Thread-2:800] [django.request:256] [base:handle_uncaught_exception] [ERROR]- Internal Server Error: /
Traceback (most recent call last):
  File "C:\Python27\lib\site-packages\django\core\handlers\base.py", line 132, in get_response
    response = wrapped_callback(request, *callback_args, **callback_kwargs)
  File "C:\Users\Administrator\PycharmProjects\blog\myblog\views.py", line 27, in index
    return render(request, 'base.html',{'category_list':category_list,})
UnboundLocalError: local variable 'category_list' referenced before assignment
2016-08-25 12:56:09,796 [Thread-4:9600] [django.request:256] [base:handle_uncaught_exception] [ERROR]- Internal Server Error: /
Traceback (most recent call last):
  File "C:\Python27\lib\site-packages\django\core\handlers\base.py", line 132, in get_response
    response = wrapped_callback(request, *callback_args, **callback_kwargs)
  File "C:\Users\Administrator\PycharmProjects\blog\myblog\views.py", line 27, in index
    return render(request, 'base.html',{'category_list':category_list,})
UnboundLocalError: local variable 'category_list' referenced before assignment
2016-08-25 12:56:11,280 [Thread-5:8292] [django.request:256] [base:handle_uncaught_exception] [ERROR]- Internal Server Error: /
Traceback (most recent call last):
  File "C:\Python27\lib\site-packages\django\core\handlers\base.py", line 132, in get_response
    response = wrapped_callback(request, *callback_args, **callback_kwargs)
  File "C:\Users\Administrator\PycharmProjects\blog\myblog\views.py", line 27, in index
    return render(request, 'base.html',{'category_list':category_list,})
UnboundLocalError: local variable 'category_list' referenced before assignment
2016-08-25 12:56:46,256 [Thread-2:8408] [django.request:256] [base:handle_uncaught_exception] [ERROR]- Internal Server Error: /
Traceback (most recent call last):
  File "C:\Python27\lib\site-packages\django\core\handlers\base.py", line 132, in get_response
    response = wrapped_callback(request, *callback_args, **callback_kwargs)
  File "C:\Users\Administrator\PycharmProjects\blog\myblog\views.py", line 25, in index
    except exception as e:
NameError: global name 'exception' is not defined
2016-08-25 12:56:54,599 [Thread-4:7096] [django.request:256] [base:handle_uncaught_exception] [ERROR]- Internal Server Error: /
Traceback (most recent call last):
  File "C:\Python27\lib\site-packages\django\core\handlers\base.py", line 132, in get_response
    response = wrapped_callback(request, *callback_args, **callback_kwargs)
  File "C:\Users\Administrator\PycharmProjects\blog\myblog\views.py", line 25, in index
    except Exception as e:
NameError: global name 'exception' is not defined
2016-08-25 13:01:25,632 [Thread-2:2812] [django.request:256] [base:handle_uncaught_exception] [ERROR]- Internal Server Error: /
Traceback (most recent call last):
  File "C:\Python27\lib\site-packages\django\core\handlers\base.py", line 132, in get_response
    response = wrapped_callback(request, *callback_args, **callback_kwargs)
  File "C:\Users\Administrator\PycharmProjects\blog\myblog\views.py", line 27, in index
    return render(request, 'base.html',{'category_list':category_list,})
UnboundLocalError: local variable 'category_list' referenced before assignment
2016-08-25 13:08:59,137 [Thread-57:800] [django.request:170] [base:get_response] [WARNING]- Not Found: /base.html
2016-08-25 13:20:39,384 [Thread-2:2080] [django.request:256] [base:handle_uncaught_exception] [ERROR]- Internal Server Error: /
Traceback (most recent call last):
  File "C:\Python27\lib\site-packages\django\core\handlers\base.py", line 119, in get_response
    resolver_match = resolver.resolve(request.path_info)
  File "C:\Python27\lib\site-packages\django\core\urlresolvers.py", line 366, in resolve
    for pattern in self.url_patterns:
  File "C:\Python27\lib\site-packages\django\core\urlresolvers.py", line 402, in url_patterns
    patterns = getattr(self.urlconf_module, "urlpatterns", self.urlconf_module)
  File "C:\Python27\lib\site-packages\django\core\urlresolvers.py", line 396, in urlconf_module
    self._urlconf_module = import_module(self.urlconf_name)
  File "C:\Python27\Lib\importlib\__init__.py", line 37, in import_module
    __import__(name)
  File "C:\Users\Administrator\PycharmProjects\blog\blog\urls.py", line 3, in <module>
    from myblog import views
  File "C:\Users\Administrator\PycharmProjects\blog\myblog\views.py", line 31
    except (InvalidPage, EmptyPage, PageNotAnInteger)
                                                    ^
SyntaxError: invalid syntax
2016-08-25 13:27:29,933 [Thread-7:10792] [django.request:256] [base:handle_uncaught_exception] [ERROR]- Internal Server Error: /
Traceback (most recent call last):
  File "C:\Python27\lib\site-packages\django\core\handlers\base.py", line 119, in get_response
    resolver_match = resolver.resolve(request.path_info)
  File "C:\Python27\lib\site-packages\django\core\urlresolvers.py", line 366, in resolve
    for pattern in self.url_patterns:
  File "C:\Python27\lib\site-packages\django\core\urlresolvers.py", line 402, in url_patterns
    patterns = getattr(self.urlconf_module, "urlpatterns", self.urlconf_module)
  File "C:\Python27\lib\site-packages\django\core\urlresolvers.py", line 396, in urlconf_module
    self._urlconf_module = import_module(self.urlconf_name)
  File "C:\Python27\Lib\importlib\__init__.py", line 37, in import_module
    __import__(name)
  File "C:\Users\Administrator\PycharmProjects\blog\blog\urls.py", line 3, in <module>
    from myblog import views
  File "C:\Users\Administrator\PycharmProjects\blog\myblog\views.py", line 31
    except (InvalidPage, EmptyPage, PageNotAnInteger)
                                                    ^
SyntaxError: invalid syntax
2016-08-25 13:29:00,717 [Thread-51:9524] [django.request:170] [base:get_response] [WARNING]- Not Found: /base.html
2016-08-25 13:29:03,105 [Thread-52:9100] [django.request:170] [base:get_response] [WARNING]- Not Found: /base.html
2016-08-25 13:29:05,171 [Thread-53:9864] [django.request:170] [base:get_response] [WARNING]- Not Found: /base.html
2016-08-25 13:53:15,845 [Thread-45:7156] [django.request:170] [base:get_response] [WARNING]- Not Found: /base.html
2016-08-25 13:55:13,736 [Thread-2:7356] [django.request:256] [base:handle_uncaught_exception] [ERROR]- Internal Server Error: /
Traceback (most recent call last):
  File "C:\Python27\lib\site-packages\django\core\handlers\base.py", line 132, in get_response
    response = wrapped_callback(request, *callback_args, **callback_kwargs)
  File "C:\Users\Administrator\PycharmProjects\blog\myblog\views.py", line 35, in index
    return render(request, 'base.html',{'category_list':category_list,'article_list':article_list,})
  File "C:\Python27\lib\site-packages\django\shortcuts.py", line 67, in render
    template_name, context, request=request, using=using)
  File "C:\Python27\lib\site-packages\django\template\loader.py", line 99, in render_to_string
    return template.render(context, request)
  File "C:\Python27\lib\site-packages\django\template\backends\django.py", line 74, in render
    return self.template.render(context)
  File "C:\Python27\lib\site-packages\django\template\base.py", line 209, in render
    return self._render(context)
  File "C:\Python27\lib\site-packages\django\template\base.py", line 201, in _render
    return self.nodelist.render(context)
  File "C:\Python27\lib\site-packages\django\template\base.py", line 903, in render
    bit = self.render_node(node, context)
  File "C:\Python27\lib\site-packages\django\template\debug.py", line 79, in render_node
    return node.render(context)
  File "C:\Python27\lib\site-packages\django\template\defaulttags.py", line 217, in render
    nodelist.append(node.render(context))
  File "C:\Python27\lib\site-packages\django\template\defaulttags.py", line 507, in render
    six.reraise(*exc_info)
  File "C:\Python27\lib\site-packages\django\template\defaulttags.py", line 493, in render
    url = reverse(view_name, args=args, kwargs=kwargs, current_app=current_app)
  File "C:\Python27\lib\site-packages\django\core\urlresolvers.py", line 579, in reverse
    return force_text(iri_to_uri(resolver._reverse_with_prefix(view, prefix, *args, **kwargs)))
  File "C:\Python27\lib\site-packages\django\core\urlresolvers.py", line 496, in _reverse_with_prefix
    (lookup_view_s, args, kwargs, len(patterns), patterns))
NoReverseMatch: Reverse for 'category' with arguments '()' and keyword arguments '{}' not found. 0 pattern(s) tried: []
2016-08-25 14:06:44,532 [Thread-9:7112] [django.request:256] [base:handle_uncaught_exception] [ERROR]- Internal Server Error: /
Traceback (most recent call last):
  File "C:\Python27\lib\site-packages\django\core\handlers\base.py", line 132, in get_response
    response = wrapped_callback(request, *callback_args, **callback_kwargs)
  File "C:\Users\Administrator\PycharmProjects\blog\myblog\views.py", line 35, in index
    return render(request, 'base.html',{'category_list':category_list,'article_list':article_list,})
  File "C:\Python27\lib\site-packages\django\shortcuts.py", line 67, in render
    template_name, context, request=request, using=using)
  File "C:\Python27\lib\site-packages\django\template\loader.py", line 99, in render_to_string
    return template.render(context, request)
  File "C:\Python27\lib\site-packages\django\template\backends\django.py", line 74, in render
    return self.template.render(context)
  File "C:\Python27\lib\site-packages\django\template\base.py", line 209, in render
    return self._render(context)
  File "C:\Python27\lib\site-packages\django\template\base.py", line 201, in _render
    return self.nodelist.render(context)
  File "C:\Python27\lib\site-packages\django\template\base.py", line 903, in render
    bit = self.render_node(node, context)
  File "C:\Python27\lib\site-packages\django\template\debug.py", line 79, in render_node
    return node.render(context)
  File "C:\Python27\lib\site-packages\django\template\defaulttags.py", line 217, in render
    nodelist.append(node.render(context))
  File "C:\Python27\lib\site-packages\django\template\defaulttags.py", line 507, in render
    six.reraise(*exc_info)
  File "C:\Python27\lib\site-packages\django\template\defaulttags.py", line 493, in render
    url = reverse(view_name, args=args, kwargs=kwargs, current_app=current_app)
  File "C:\Python27\lib\site-packages\django\core\urlresolvers.py", line 579, in reverse
    return force_text(iri_to_uri(resolver._reverse_with_prefix(view, prefix, *args, **kwargs)))
  File "C:\Python27\lib\site-packages\django\core\urlresolvers.py", line 496, in _reverse_with_prefix
    (lookup_view_s, args, kwargs, len(patterns), patterns))
NoReverseMatch: Reverse for 'category' with arguments '()' and keyword arguments '{}' not found. 0 pattern(s) tried: []
2016-08-25 14:07:22,128 [Thread-10:2012] [django.request:256] [base:handle_uncaught_exception] [ERROR]- Internal Server Error: /
Traceback (most recent call last):
  File "C:\Python27\lib\site-packages\django\core\handlers\base.py", line 132, in get_response
    response = wrapped_callback(request, *callback_args, **callback_kwargs)
  File "C:\Users\Administrator\PycharmProjects\blog\myblog\views.py", line 35, in index
    return render(request, 'base.html',{'category_list':category_list,'article_list':article_list,})
  File "C:\Python27\lib\site-packages\django\shortcuts.py", line 67, in render
    template_name, context, request=request, using=using)
  File "C:\Python27\lib\site-packages\django\template\loader.py", line 99, in render_to_string
    return template.render(context, request)
  File "C:\Python27\lib\site-packages\django\template\backends\django.py", line 74, in render
    return self.template.render(context)
  File "C:\Python27\lib\site-packages\django\template\base.py", line 209, in render
    return self._render(context)
  File "C:\Python27\lib\site-packages\django\template\base.py", line 201, in _render
    return self.nodelist.render(context)
  File "C:\Python27\lib\site-packages\django\template\base.py", line 903, in render
    bit = self.render_node(node, context)
  File "C:\Python27\lib\site-packages\django\template\debug.py", line 79, in render_node
    return node.render(context)
  File "C:\Python27\lib\site-packages\django\template\defaulttags.py", line 217, in render
    nodelist.append(node.render(context))
  File "C:\Python27\lib\site-packages\django\template\defaulttags.py", line 507, in render
    six.reraise(*exc_info)
  File "C:\Python27\lib\site-packages\django\template\defaulttags.py", line 493, in render
    url = reverse(view_name, args=args, kwargs=kwargs, current_app=current_app)
  File "C:\Python27\lib\site-packages\django\core\urlresolvers.py", line 579, in reverse
    return force_text(iri_to_uri(resolver._reverse_with_prefix(view, prefix, *args, **kwargs)))
  File "C:\Python27\lib\site-packages\django\core\urlresolvers.py", line 496, in _reverse_with_prefix
    (lookup_view_s, args, kwargs, len(patterns), patterns))
NoReverseMatch: Reverse for 'category' with arguments '()' and keyword arguments '{}' not found. 0 pattern(s) tried: []
2016-08-25 17:44:17,134 [Thread-2:22568] [django.request:256] [base:handle_uncaught_exception] [ERROR]- Internal Server Error: /
Traceback (most recent call last):
  File "C:\Python27\lib\site-packages\django\core\handlers\base.py", line 119, in get_response
    resolver_match = resolver.resolve(request.path_info)
  File "C:\Python27\lib\site-packages\django\core\urlresolvers.py", line 366, in resolve
    for pattern in self.url_patterns:
  File "C:\Python27\lib\site-packages\django\core\urlresolvers.py", line 402, in url_patterns
    patterns = getattr(self.urlconf_module, "urlpatterns", self.urlconf_module)
  File "C:\Python27\lib\site-packages\django\core\urlresolvers.py", line 396, in urlconf_module
    self._urlconf_module = import_module(self.urlconf_name)
  File "C:\Python27\Lib\importlib\__init__.py", line 37, in import_module
    __import__(name)
  File "C:\Users\Administrator\PycharmProjects\blog\blog\urls.py", line 12, in <module>
    url(r'^', include('myblog.urls')),
  File "C:\Python27\lib\site-packages\django\conf\urls\__init__.py", line 33, in include
    urlconf_module = import_module(urlconf_module)
  File "C:\Python27\Lib\importlib\__init__.py", line 37, in import_module
    __import__(name)
  File "C:\Users\Administrator\PycharmProjects\blog\myblog\urls.py", line 11, in <module>
    url(r'^article/$',views.article,name='article'),
AttributeError: 'module' object has no attribute 'article'
2016-08-26 10:41:22,278 [Thread-2:8376] [django.request:256] [base:handle_uncaught_exception] [ERROR]- Internal Server Error: /
Traceback (most recent call last):
  File "C:\Python27\lib\site-packages\django\core\handlers\base.py", line 119, in get_response
    resolver_match = resolver.resolve(request.path_info)
  File "C:\Python27\lib\site-packages\django\core\urlresolvers.py", line 366, in resolve
    for pattern in self.url_patterns:
  File "C:\Python27\lib\site-packages\django\core\urlresolvers.py", line 402, in url_patterns
    patterns = getattr(self.urlconf_module, "urlpatterns", self.urlconf_module)
  File "C:\Python27\lib\site-packages\django\core\urlresolvers.py", line 396, in urlconf_module
    self._urlconf_module = import_module(self.urlconf_name)
  File "C:\Python27\Lib\importlib\__init__.py", line 37, in import_module
    __import__(name)
  File "C:\Users\Administrator\PycharmProjects\blog\blog\urls.py", line 12, in <module>
    url(r'^', include('myblog.urls')),
  File "C:\Python27\lib\site-packages\django\conf\urls\__init__.py", line 33, in include
    urlconf_module = import_module(urlconf_module)
  File "C:\Python27\Lib\importlib\__init__.py", line 37, in import_module
    __import__(name)
  File "C:\Users\Administrator\PycharmProjects\blog\myblog\urls.py", line 3, in <module>
    from myblog import views
  File "C:\Users\Administrator\PycharmProjects\blog\myblog\views.py", line 153
    def do_login(request):
                         ^
IndentationError: expected an indented block
2016-08-26 10:41:23,134 [Thread-3:9148] [django.request:256] [base:handle_uncaught_exception] [ERROR]- Internal Server Error: /favicon.ico
Traceback (most recent call last):
  File "C:\Python27\lib\site-packages\django\core\handlers\base.py", line 108, in get_response
    response = middleware_method(request)
  File "C:\Python27\lib\site-packages\django\middleware\common.py", line 74, in process_request
    if (not urlresolvers.is_valid_path(request.path_info, urlconf) and
  File "C:\Python27\lib\site-packages\django\core\urlresolvers.py", line 647, in is_valid_path
    resolve(path, urlconf)
  File "C:\Python27\lib\site-packages\django\core\urlresolvers.py", line 522, in resolve
    return get_resolver(urlconf).resolve(path)
  File "C:\Python27\lib\site-packages\django\core\urlresolvers.py", line 366, in resolve
    for pattern in self.url_patterns:
  File "C:\Python27\lib\site-packages\django\core\urlresolvers.py", line 402, in url_patterns
    patterns = getattr(self.urlconf_module, "urlpatterns", self.urlconf_module)
  File "C:\Python27\lib\site-packages\django\core\urlresolvers.py", line 396, in urlconf_module
    self._urlconf_module = import_module(self.urlconf_name)
  File "C:\Python27\Lib\importlib\__init__.py", line 37, in import_module
    __import__(name)
  File "C:\Users\Administrator\PycharmProjects\blog\blog\urls.py", line 12, in <module>
    url(r'^', include('myblog.urls')),
  File "C:\Python27\lib\site-packages\django\conf\urls\__init__.py", line 33, in include
    urlconf_module = import_module(urlconf_module)
  File "C:\Python27\Lib\importlib\__init__.py", line 37, in import_module
    __import__(name)
  File "C:\Users\Administrator\PycharmProjects\blog\myblog\urls.py", line 3, in <module>
    from myblog import views
  File "C:\Users\Administrator\PycharmProjects\blog\myblog\views.py", line 153
    def do_login(request):
                         ^
IndentationError: expected an indented block
2016-08-26 10:41:23,391 [Thread-4:8140] [django.request:256] [base:handle_uncaught_exception] [ERROR]- Internal Server Error: /favicon.ico
Traceback (most recent call last):
  File "C:\Python27\lib\site-packages\django\core\handlers\base.py", line 108, in get_response
    response = middleware_method(request)
  File "C:\Python27\lib\site-packages\django\middleware\common.py", line 74, in process_request
    if (not urlresolvers.is_valid_path(request.path_info, urlconf) and
  File "C:\Python27\lib\site-packages\django\core\urlresolvers.py", line 647, in is_valid_path
    resolve(path, urlconf)
  File "C:\Python27\lib\site-packages\django\core\urlresolvers.py", line 522, in resolve
    return get_resolver(urlconf).resolve(path)
  File "C:\Python27\lib\site-packages\django\core\urlresolvers.py", line 366, in resolve
    for pattern in self.url_patterns:
  File "C:\Python27\lib\site-packages\django\core\urlresolvers.py", line 402, in url_patterns
    patterns = getattr(self.urlconf_module, "urlpatterns", self.urlconf_module)
  File "C:\Python27\lib\site-packages\django\core\urlresolvers.py", line 396, in urlconf_module
    self._urlconf_module = import_module(self.urlconf_name)
  File "C:\Python27\Lib\importlib\__init__.py", line 37, in import_module
    __import__(name)
  File "C:\Users\Administrator\PycharmProjects\blog\blog\urls.py", line 12, in <module>
    url(r'^', include('myblog.urls')),
  File "C:\Python27\lib\site-packages\django\conf\urls\__init__.py", line 33, in include
    urlconf_module = import_module(urlconf_module)
  File "C:\Python27\Lib\importlib\__init__.py", line 37, in import_module
    __import__(name)
  File "C:\Users\Administrator\PycharmProjects\blog\myblog\urls.py", line 3, in <module>
    from myblog import views
  File "C:\Users\Administrator\PycharmProjects\blog\myblog\views.py", line 153
    def do_login(request):
                         ^
IndentationError: expected an indented block
2016-08-26 10:43:11,513 [Thread-5:7772] [django.request:256] [base:handle_uncaught_exception] [ERROR]- Internal Server Error: /
Traceback (most recent call last):
  File "C:\Python27\lib\site-packages\django\core\handlers\base.py", line 119, in get_response
    resolver_match = resolver.resolve(request.path_info)
  File "C:\Python27\lib\site-packages\django\core\urlresolvers.py", line 366, in resolve
    for pattern in self.url_patterns:
  File "C:\Python27\lib\site-packages\django\core\urlresolvers.py", line 402, in url_patterns
    patterns = getattr(self.urlconf_module, "urlpatterns", self.urlconf_module)
  File "C:\Python27\lib\site-packages\django\core\urlresolvers.py", line 396, in urlconf_module
    self._urlconf_module = import_module(self.urlconf_name)
  File "C:\Python27\Lib\importlib\__init__.py", line 37, in import_module
    __import__(name)
  File "C:\Users\Administrator\PycharmProjects\blog\blog\urls.py", line 12, in <module>
    url(r'^', include('myblog.urls')),
  File "C:\Python27\lib\site-packages\django\conf\urls\__init__.py", line 33, in include
    urlconf_module = import_module(urlconf_module)
  File "C:\Python27\Lib\importlib\__init__.py", line 37, in import_module
    __import__(name)
  File "C:\Users\Administrator\PycharmProjects\blog\myblog\urls.py", line 3, in <module>
    from myblog import views
  File "C:\Users\Administrator\PycharmProjects\blog\myblog\views.py", line 154
    def do_login(request):
                         ^
IndentationError: expected an indented block
2016-08-26 10:45:12,125 [Thread-6:7144] [django.request:256] [base:handle_uncaught_exception] [ERROR]- Internal Server Error: /
Traceback (most recent call last):
  File "C:\Python27\lib\site-packages\django\core\handlers\base.py", line 119, in get_response
    resolver_match = resolver.resolve(request.path_info)
  File "C:\Python27\lib\site-packages\django\core\urlresolvers.py", line 366, in resolve
    for pattern in self.url_patterns:
  File "C:\Python27\lib\site-packages\django\core\urlresolvers.py", line 402, in url_patterns
    patterns = getattr(self.urlconf_module, "urlpatterns", self.urlconf_module)
  File "C:\Python27\lib\site-packages\django\core\urlresolvers.py", line 396, in urlconf_module
    self._urlconf_module = import_module(self.urlconf_name)
  File "C:\Python27\Lib\importlib\__init__.py", line 37, in import_module
    __import__(name)
  File "C:\Users\Administrator\PycharmProjects\blog\blog\urls.py", line 12, in <module>
    url(r'^', include('myblog.urls')),
  File "C:\Python27\lib\site-packages\django\conf\urls\__init__.py", line 33, in include
    urlconf_module = import_module(urlconf_module)
  File "C:\Python27\Lib\importlib\__init__.py", line 37, in import_module
    __import__(name)
  File "C:\Users\Administrator\PycharmProjects\blog\myblog\urls.py", line 3, in <module>
    from myblog import views
  File "C:\Users\Administrator\PycharmProjects\blog\myblog\views.py", line 154
    def do_login(request):
                         ^
IndentationError: expected an indented block
2016-08-26 10:45:15,130 [Thread-7:9196] [django.request:256] [base:handle_uncaught_exception] [ERROR]- Internal Server Error: /
Traceback (most recent call last):
  File "C:\Python27\lib\site-packages\django\core\handlers\base.py", line 119, in get_response
    resolver_match = resolver.resolve(request.path_info)
  File "C:\Python27\lib\site-packages\django\core\urlresolvers.py", line 366, in resolve
    for pattern in self.url_patterns:
  File "C:\Python27\lib\site-packages\django\core\urlresolvers.py", line 402, in url_patterns
    patterns = getattr(self.urlconf_module, "urlpatterns", self.urlconf_module)
  File "C:\Python27\lib\site-packages\django\core\urlresolvers.py", line 396, in urlconf_module
    self._urlconf_module = import_module(self.urlconf_name)
  File "C:\Python27\Lib\importlib\__init__.py", line 37, in import_module
    __import__(name)
  File "C:\Users\Administrator\PycharmProjects\blog\blog\urls.py", line 12, in <module>
    url(r'^', include('myblog.urls')),
  File "C:\Python27\lib\site-packages\django\conf\urls\__init__.py", line 33, in include
    urlconf_module = import_module(urlconf_module)
  File "C:\Python27\Lib\importlib\__init__.py", line 37, in import_module
    __import__(name)
  File "C:\Users\Administrator\PycharmProjects\blog\myblog\urls.py", line 3, in <module>
    from myblog import views
  File "C:\Users\Administrator\PycharmProjects\blog\myblog\views.py", line 154
    def do_login(request):
                         ^
IndentationError: expected an indented block
2016-08-26 10:45:15,263 [Thread-8:8328] [django.request:256] [base:handle_uncaught_exception] [ERROR]- Internal Server Error: /
Traceback (most recent call last):
  File "C:\Python27\lib\site-packages\django\core\handlers\base.py", line 119, in get_response
    resolver_match = resolver.resolve(request.path_info)
  File "C:\Python27\lib\site-packages\django\core\urlresolvers.py", line 366, in resolve
    for pattern in self.url_patterns:
  File "C:\Python27\lib\site-packages\django\core\urlresolvers.py", line 402, in url_patterns
    patterns = getattr(self.urlconf_module, "urlpatterns", self.urlconf_module)
  File "C:\Python27\lib\site-packages\django\core\urlresolvers.py", line 396, in urlconf_module
    self._urlconf_module = import_module(self.urlconf_name)
  File "C:\Python27\Lib\importlib\__init__.py", line 37, in import_module
    __import__(name)
  File "C:\Users\Administrator\PycharmProjects\blog\blog\urls.py", line 12, in <module>
    url(r'^', include('myblog.urls')),
  File "C:\Python27\lib\site-packages\django\conf\urls\__init__.py", line 33, in include
    urlconf_module = import_module(urlconf_module)
  File "C:\Python27\Lib\importlib\__init__.py", line 37, in import_module
    __import__(name)
  File "C:\Users\Administrator\PycharmProjects\blog\myblog\urls.py", line 3, in <module>
    from myblog import views
  File "C:\Users\Administrator\PycharmProjects\blog\myblog\views.py", line 154
    def do_login(request):
                         ^
IndentationError: expected an indented block
2016-08-26 10:45:15,446 [Thread-9:1540] [django.request:256] [base:handle_uncaught_exception] [ERROR]- Internal Server Error: /
Traceback (most recent call last):
  File "C:\Python27\lib\site-packages\django\core\handlers\base.py", line 119, in get_response
    resolver_match = resolver.resolve(request.path_info)
  File "C:\Python27\lib\site-packages\django\core\urlresolvers.py", line 366, in resolve
    for pattern in self.url_patterns:
  File "C:\Python27\lib\site-packages\django\core\urlresolvers.py", line 402, in url_patterns
    patterns = getattr(self.urlconf_module, "urlpatterns", self.urlconf_module)
  File "C:\Python27\lib\site-packages\django\core\urlresolvers.py", line 396, in urlconf_module
    self._urlconf_module = import_module(self.urlconf_name)
  File "C:\Python27\Lib\importlib\__init__.py", line 37, in import_module
    __import__(name)
  File "C:\Users\Administrator\PycharmProjects\blog\blog\urls.py", line 12, in <module>
    url(r'^', include('myblog.urls')),
  File "C:\Python27\lib\site-packages\django\conf\urls\__init__.py", line 33, in include
    urlconf_module = import_module(urlconf_module)
  File "C:\Python27\Lib\importlib\__init__.py", line 37, in import_module
    __import__(name)
  File "C:\Users\Administrator\PycharmProjects\blog\myblog\urls.py", line 3, in <module>
    from myblog import views
  File "C:\Users\Administrator\PycharmProjects\blog\myblog\views.py", line 154
    def do_login(request):
                         ^
IndentationError: expected an indented block
2016-08-26 10:45:15,618 [Thread-10:4580] [django.request:256] [base:handle_uncaught_exception] [ERROR]- Internal Server Error: /
Traceback (most recent call last):
  File "C:\Python27\lib\site-packages\django\core\handlers\base.py", line 119, in get_response
    resolver_match = resolver.resolve(request.path_info)
  File "C:\Python27\lib\site-packages\django\core\urlresolvers.py", line 366, in resolve
    for pattern in self.url_patterns:
  File "C:\Python27\lib\site-packages\django\core\urlresolvers.py", line 402, in url_patterns
    patterns = getattr(self.urlconf_module, "urlpatterns", self.urlconf_module)
  File "C:\Python27\lib\site-packages\django\core\urlresolvers.py", line 396, in urlconf_module
    self._urlconf_module = import_module(self.urlconf_name)
  File "C:\Python27\Lib\importlib\__init__.py", line 37, in import_module
    __import__(name)
  File "C:\Users\Administrator\PycharmProjects\blog\blog\urls.py", line 12, in <module>
    url(r'^', include('myblog.urls')),
  File "C:\Python27\lib\site-packages\django\conf\urls\__init__.py", line 33, in include
    urlconf_module = import_module(urlconf_module)
  File "C:\Python27\Lib\importlib\__init__.py", line 37, in import_module
    __import__(name)
  File "C:\Users\Administrator\PycharmProjects\blog\myblog\urls.py", line 3, in <module>
    from myblog import views
  File "C:\Users\Administrator\PycharmProjects\blog\myblog\views.py", line 154
    def do_login(request):
                         ^
IndentationError: expected an indented block
2016-08-26 10:45:15,806 [Thread-11:4952] [django.request:256] [base:handle_uncaught_exception] [ERROR]- Internal Server Error: /
Traceback (most recent call last):
  File "C:\Python27\lib\site-packages\django\core\handlers\base.py", line 119, in get_response
    resolver_match = resolver.resolve(request.path_info)
  File "C:\Python27\lib\site-packages\django\core\urlresolvers.py", line 366, in resolve
    for pattern in self.url_patterns:
  File "C:\Python27\lib\site-packages\django\core\urlresolvers.py", line 402, in url_patterns
    patterns = getattr(self.urlconf_module, "urlpatterns", self.urlconf_module)
  File "C:\Python27\lib\site-packages\django\core\urlresolvers.py", line 396, in urlconf_module
    self._urlconf_module = import_module(self.urlconf_name)
  File "C:\Python27\Lib\importlib\__init__.py", line 37, in import_module
    __import__(name)
  File "C:\Users\Administrator\PycharmProjects\blog\blog\urls.py", line 12, in <module>
    url(r'^', include('myblog.urls')),
  File "C:\Python27\lib\site-packages\django\conf\urls\__init__.py", line 33, in include
    urlconf_module = import_module(urlconf_module)
  File "C:\Python27\Lib\importlib\__init__.py", line 37, in import_module
    __import__(name)
  File "C:\Users\Administrator\PycharmProjects\blog\myblog\urls.py", line 3, in <module>
    from myblog import views
  File "C:\Users\Administrator\PycharmProjects\blog\myblog\views.py", line 154
    def do_login(request):
                         ^
IndentationError: expected an indented block
2016-08-26 10:45:19,380 [Thread-12:8228] [django.request:256] [base:handle_uncaught_exception] [ERROR]- Internal Server Error: /admin/
Traceback (most recent call last):
  File "C:\Python27\lib\site-packages\django\core\handlers\base.py", line 119, in get_response
    resolver_match = resolver.resolve(request.path_info)
  File "C:\Python27\lib\site-packages\django\core\urlresolvers.py", line 366, in resolve
    for pattern in self.url_patterns:
  File "C:\Python27\lib\site-packages\django\core\urlresolvers.py", line 402, in url_patterns
    patterns = getattr(self.urlconf_module, "urlpatterns", self.urlconf_module)
  File "C:\Python27\lib\site-packages\django\core\urlresolvers.py", line 396, in urlconf_module
    self._urlconf_module = import_module(self.urlconf_name)
  File "C:\Python27\Lib\importlib\__init__.py", line 37, in import_module
    __import__(name)
  File "C:\Users\Administrator\PycharmProjects\blog\blog\urls.py", line 12, in <module>
    url(r'^', include('myblog.urls')),
  File "C:\Python27\lib\site-packages\django\conf\urls\__init__.py", line 33, in include
    urlconf_module = import_module(urlconf_module)
  File "C:\Python27\Lib\importlib\__init__.py", line 37, in import_module
    __import__(name)
  File "C:\Users\Administrator\PycharmProjects\blog\myblog\urls.py", line 3, in <module>
    from myblog import views
  File "C:\Users\Administrator\PycharmProjects\blog\myblog\views.py", line 154
    def do_login(request):
                         ^
IndentationError: expected an indented block
2016-08-26 10:46:20,609 [Thread-13:8228] [django.request:256] [base:handle_uncaught_exception] [ERROR]- Internal Server Error: /admin/
Traceback (most recent call last):
  File "C:\Python27\lib\site-packages\django\core\handlers\base.py", line 119, in get_response
    resolver_match = resolver.resolve(request.path_info)
  File "C:\Python27\lib\site-packages\django\core\urlresolvers.py", line 366, in resolve
    for pattern in self.url_patterns:
  File "C:\Python27\lib\site-packages\django\core\urlresolvers.py", line 402, in url_patterns
    patterns = getattr(self.urlconf_module, "urlpatterns", self.urlconf_module)
  File "C:\Python27\lib\site-packages\django\core\urlresolvers.py", line 396, in urlconf_module
    self._urlconf_module = import_module(self.urlconf_name)
  File "C:\Python27\Lib\importlib\__init__.py", line 37, in import_module
    __import__(name)
  File "C:\Users\Administrator\PycharmProjects\blog\blog\urls.py", line 12, in <module>
    url(r'^', include('myblog.urls')),
  File "C:\Python27\lib\site-packages\django\conf\urls\__init__.py", line 33, in include
    urlconf_module = import_module(urlconf_module)
  File "C:\Python27\Lib\importlib\__init__.py", line 37, in import_module
    __import__(name)
  File "C:\Users\Administrator\PycharmProjects\blog\myblog\urls.py", line 3, in <module>
    from myblog import views
  File "C:\Users\Administrator\PycharmProjects\blog\myblog\views.py", line 187
    
    ^
IndentationError: expected an indented block
2016-08-26 10:54:52,977 [Thread-14:9096] [django.request:256] [base:handle_uncaught_exception] [ERROR]- Internal Server Error: /admin/
Traceback (most recent call last):
  File "C:\Python27\lib\site-packages\django\core\handlers\base.py", line 119, in get_response
    resolver_match = resolver.resolve(request.path_info)
  File "C:\Python27\lib\site-packages\django\core\urlresolvers.py", line 366, in resolve
    for pattern in self.url_patterns:
  File "C:\Python27\lib\site-packages\django\core\urlresolvers.py", line 402, in url_patterns
    patterns = getattr(self.urlconf_module, "urlpatterns", self.urlconf_module)
  File "C:\Python27\lib\site-packages\django\core\urlresolvers.py", line 396, in urlconf_module
    self._urlconf_module = import_module(self.urlconf_name)
  File "C:\Python27\Lib\importlib\__init__.py", line 37, in import_module
    __import__(name)
  File "C:\Users\Administrator\PycharmProjects\blog\blog\urls.py", line 12, in <module>
    url(r'^', include('myblog.urls')),
  File "C:\Python27\lib\site-packages\django\conf\urls\__init__.py", line 33, in include
    urlconf_module = import_module(urlconf_module)
  File "C:\Python27\Lib\importlib\__init__.py", line 37, in import_module
    __import__(name)
  File "C:\Users\Administrator\PycharmProjects\blog\myblog\urls.py", line 2, in <module>
    from myblog import views
  File "C:\Users\Administrator\PycharmProjects\blog\myblog\views.py", line 154
    def do_login(request):
                         ^
IndentationError: expected an indented block
2016-08-26 10:55:22,976 [Thread-15:8328] [django.request:256] [base:handle_uncaught_exception] [ERROR]- Internal Server Error: /admin/
Traceback (most recent call last):
  File "C:\Python27\lib\site-packages\django\core\handlers\base.py", line 119, in get_response
    resolver_match = resolver.resolve(request.path_info)
  File "C:\Python27\lib\site-packages\django\core\urlresolvers.py", line 366, in resolve
    for pattern in self.url_patterns:
  File "C:\Python27\lib\site-packages\django\core\urlresolvers.py", line 402, in url_patterns
    patterns = getattr(self.urlconf_module, "urlpatterns", self.urlconf_module)
  File "C:\Python27\lib\site-packages\django\core\urlresolvers.py", line 396, in urlconf_module
    self._urlconf_module = import_module(self.urlconf_name)
  File "C:\Python27\Lib\importlib\__init__.py", line 37, in import_module
    __import__(name)
  File "C:\Users\Administrator\PycharmProjects\blog\blog\urls.py", line 12, in <module>
    url(r'^', include('myblog.urls')),
  File "C:\Python27\lib\site-packages\django\conf\urls\__init__.py", line 33, in include
    urlconf_module = import_module(urlconf_module)
  File "C:\Python27\Lib\importlib\__init__.py", line 37, in import_module
    __import__(name)
  File "C:\Users\Administrator\PycharmProjects\blog\myblog\urls.py", line 2, in <module>
    from myblog import views
  File "C:\Users\Administrator\PycharmProjects\blog\myblog\views.py", line 153
    def do_login(request):
                         ^
IndentationError: expected an indented block
2016-08-26 10:55:27,845 [Thread-16:4616] [django.request:256] [base:handle_uncaught_exception] [ERROR]- Internal Server Error: /admin/
Traceback (most recent call last):
  File "C:\Python27\lib\site-packages\django\core\handlers\base.py", line 119, in get_response
    resolver_match = resolver.resolve(request.path_info)
  File "C:\Python27\lib\site-packages\django\core\urlresolvers.py", line 366, in resolve
    for pattern in self.url_patterns:
  File "C:\Python27\lib\site-packages\django\core\urlresolvers.py", line 402, in url_patterns
    patterns = getattr(self.urlconf_module, "urlpatterns", self.urlconf_module)
  File "C:\Python27\lib\site-packages\django\core\urlresolvers.py", line 396, in urlconf_module
    self._urlconf_module = import_module(self.urlconf_name)
  File "C:\Python27\Lib\importlib\__init__.py", line 37, in import_module
    __import__(name)
  File "C:\Users\Administrator\PycharmProjects\blog\blog\urls.py", line 12, in <module>
    url(r'^', include('myblog.urls')),
  File "C:\Python27\lib\site-packages\django\conf\urls\__init__.py", line 33, in include
    urlconf_module = import_module(urlconf_module)
  File "C:\Python27\Lib\importlib\__init__.py", line 37, in import_module
    __import__(name)
  File "C:\Users\Administrator\PycharmProjects\blog\myblog\urls.py", line 2, in <module>
    from myblog import views
  File "C:\Users\Administrator\PycharmProjects\blog\myblog\views.py", line 153
    def do_login(request):
                         ^
IndentationError: expected an indented block
2016-08-26 12:48:12,329 [Thread-2:9536] [django.request:256] [base:handle_uncaught_exception] [ERROR]- Internal Server Error: /
Traceback (most recent call last):
  File "C:\Python27\lib\site-packages\django\core\handlers\base.py", line 132, in get_response
    response = wrapped_callback(request, *callback_args, **callback_kwargs)
  File "C:\Users\Administrator\PycharmProjects\blog\myblog\views.py", line 59, in index
    return render(request, 'base.html',{'category_list':category_list,'article_list':article_list,})
NameError: global name 'category_list' is not defined
2016-08-26 12:52:21,947 [Thread-2:9104] [django.request:256] [base:handle_uncaught_exception] [ERROR]- Internal Server Error: /
Traceback (most recent call last):
  File "C:\Python27\lib\site-packages\django\core\handlers\base.py", line 132, in get_response
    response = wrapped_callback(request, *callback_args, **callback_kwargs)
  File "C:\Users\Administrator\PycharmProjects\blog\myblog\views.py", line 59, in index
    return render(request, 'base.html',locals())
  File "C:\Python27\lib\site-packages\django\shortcuts.py", line 67, in render
    template_name, context, request=request, using=using)
  File "C:\Python27\lib\site-packages\django\template\loader.py", line 99, in render_to_string
    return template.render(context, request)
  File "C:\Python27\lib\site-packages\django\template\backends\django.py", line 74, in render
    return self.template.render(context)
  File "C:\Python27\lib\site-packages\django\template\base.py", line 208, in render
    with context.bind_template(self):
  File "C:\Python27\Lib\contextlib.py", line 17, in __enter__
    return self.gen.next()
  File "C:\Python27\lib\site-packages\django\template\context.py", line 235, in bind_template
    updates.update(processor(self.request))
  File "C:\Users\Administrator\PycharmProjects\blog\myblog\views.py", line 29, in global_setting
    archive_list = Article.objects.distinct_date()
AttributeError: 'Manager' object has no attribute 'distinct_date'
2016-08-26 13:16:37,648 [Thread-3:6168] [django.request:256] [base:handle_uncaught_exception] [ERROR]- Internal Server Error: /
Traceback (most recent call last):
  File "C:\Python27\lib\site-packages\django\core\handlers\base.py", line 132, in get_response
    response = wrapped_callback(request, *callback_args, **callback_kwargs)
  File "C:\Users\Administrator\PycharmProjects\blog\myblog\views.py", line 59, in index
    return render(request, 'base.html',locals())
  File "C:\Python27\lib\site-packages\django\shortcuts.py", line 67, in render
    template_name, context, request=request, using=using)
  File "C:\Python27\lib\site-packages\django\template\loader.py", line 99, in render_to_string
    return template.render(context, request)
  File "C:\Python27\lib\site-packages\django\template\backends\django.py", line 74, in render
    return self.template.render(context)
  File "C:\Python27\lib\site-packages\django\template\base.py", line 208, in render
    with context.bind_template(self):
  File "C:\Python27\Lib\contextlib.py", line 17, in __enter__
    return self.gen.next()
  File "C:\Python27\lib\site-packages\django\template\context.py", line 235, in bind_template
    updates.update(processor(self.request))
  File "C:\Users\Administrator\PycharmProjects\blog\myblog\views.py", line 29, in global_setting
    archive_list = Article.objects.distinct_date()
AttributeError: 'Manager' object has no attribute 'distinct_date'
2016-08-26 13:40:51,766 [Thread-2:6796] [django.request:256] [base:handle_uncaught_exception] [ERROR]- Internal Server Error: /
Traceback (most recent call last):
  File "C:\Python27\lib\site-packages\django\core\handlers\base.py", line 132, in get_response
    response = wrapped_callback(request, *callback_args, **callback_kwargs)
  File "C:\Users\Administrator\PycharmProjects\blog\myblog\views.py", line 61, in index
    return render(request, 'base.html',locals())
  File "C:\Python27\lib\site-packages\django\shortcuts.py", line 67, in render
    template_name, context, request=request, using=using)
  File "C:\Python27\lib\site-packages\django\template\loader.py", line 99, in render_to_string
    return template.render(context, request)
  File "C:\Python27\lib\site-packages\django\template\backends\django.py", line 74, in render
    return self.template.render(context)
  File "C:\Python27\lib\site-packages\django\template\base.py", line 208, in render
    with context.bind_template(self):
  File "C:\Python27\Lib\contextlib.py", line 17, in __enter__
    return self.gen.next()
  File "C:\Python27\lib\site-packages\django\template\context.py", line 235, in bind_template
    updates.update(processor(self.request))
  File "C:\Users\Administrator\PycharmProjects\blog\myblog\views.py", line 31, in global_setting
    archive_list = Article.objects.distinct_date()
AttributeError: 'Manager' object has no attribute 'distinct_date'
2016-08-26 14:15:15,204 [Thread-2:8376] [django.request:256] [base:handle_uncaught_exception] [ERROR]- Internal Server Error: /
Traceback (most recent call last):
  File "C:\Python27\lib\site-packages\django\core\handlers\base.py", line 132, in get_response
    response = wrapped_callback(request, *callback_args, **callback_kwargs)
  File "C:\Users\Administrator\PycharmProjects\blog\myblog\views.py", line 59, in index
    return render(request, 'base.html',locals())
  File "C:\Python27\lib\site-packages\django\shortcuts.py", line 67, in render
    template_name, context, request=request, using=using)
  File "C:\Python27\lib\site-packages\django\template\loader.py", line 99, in render_to_string
    return template.render(context, request)
  File "C:\Python27\lib\site-packages\django\template\backends\django.py", line 74, in render
    return self.template.render(context)
  File "C:\Python27\lib\site-packages\django\template\base.py", line 208, in render
    with context.bind_template(self):
  File "C:\Python27\Lib\contextlib.py", line 17, in __enter__
    return self.gen.next()
  File "C:\Python27\lib\site-packages\django\template\context.py", line 235, in bind_template
    updates.update(processor(self.request))
  File "C:\Users\Administrator\PycharmProjects\blog\myblog\views.py", line 29, in global_setting
    archive_list = Article.objects.distinct_date()
AttributeError: 'Manager' object has no attribute 'distinct_date'
2016-08-26 19:00:53,660 [Thread-2:9180] [django.request:256] [base:handle_uncaught_exception] [ERROR]- Internal Server Error: /
Traceback (most recent call last):
  File "C:\Python27\lib\site-packages\django\core\handlers\base.py", line 119, in get_response
    resolver_match = resolver.resolve(request.path_info)
  File "C:\Python27\lib\site-packages\django\core\urlresolvers.py", line 366, in resolve
    for pattern in self.url_patterns:
  File "C:\Python27\lib\site-packages\django\core\urlresolvers.py", line 402, in url_patterns
    patterns = getattr(self.urlconf_module, "urlpatterns", self.urlconf_module)
  File "C:\Python27\lib\site-packages\django\core\urlresolvers.py", line 396, in urlconf_module
    self._urlconf_module = import_module(self.urlconf_name)
  File "C:\Python27\Lib\importlib\__init__.py", line 37, in import_module
    __import__(name)
  File "C:\Users\Administrator\PycharmProjects\blog\blog\urls.py", line 12, in <module>
    url(r'^', include('myblog.urls')),
  File "C:\Python27\lib\site-packages\django\conf\urls\__init__.py", line 33, in include
    urlconf_module = import_module(urlconf_module)
  File "C:\Python27\Lib\importlib\__init__.py", line 37, in import_module
    __import__(name)
  File "C:\Users\Administrator\PycharmProjects\blog\myblog\urls.py", line 16, in <module>
    url(r'^tag/$',views.tag,name='tag'),
AttributeError: 'module' object has no attribute 'tag'
2016-08-26 19:02:54,835 [Thread-3:10012] [django.request:256] [base:handle_uncaught_exception] [ERROR]- Internal Server Error: /
Traceback (most recent call last):
  File "C:\Python27\lib\site-packages\django\core\handlers\base.py", line 119, in get_response
    resolver_match = resolver.resolve(request.path_info)
  File "C:\Python27\lib\site-packages\django\core\urlresolvers.py", line 366, in resolve
    for pattern in self.url_patterns:
  File "C:\Python27\lib\site-packages\django\core\urlresolvers.py", line 402, in url_patterns
    patterns = getattr(self.urlconf_module, "urlpatterns", self.urlconf_module)
  File "C:\Python27\lib\site-packages\django\core\urlresolvers.py", line 396, in urlconf_module
    self._urlconf_module = import_module(self.urlconf_name)
  File "C:\Python27\Lib\importlib\__init__.py", line 37, in import_module
    __import__(name)
  File "C:\Users\Administrator\PycharmProjects\blog\blog\urls.py", line 12, in <module>
    url(r'^', include('myblog.urls')),
  File "C:\Python27\lib\site-packages\django\conf\urls\__init__.py", line 33, in include
    urlconf_module = import_module(urlconf_module)
  File "C:\Python27\Lib\importlib\__init__.py", line 37, in import_module
    __import__(name)
  File "C:\Users\Administrator\PycharmProjects\blog\myblog\urls.py", line 16, in <module>
    url(r'^tag/$',views.tag,name='tag'),
AttributeError: 'module' object has no attribute 'tag'
2016-08-26 19:03:14,417 [Thread-2:460] [django.request:256] [base:handle_uncaught_exception] [ERROR]- Internal Server Error: /
Traceback (most recent call last):
  File "C:\Python27\lib\site-packages\django\core\handlers\base.py", line 119, in get_response
    resolver_match = resolver.resolve(request.path_info)
  File "C:\Python27\lib\site-packages\django\core\urlresolvers.py", line 366, in resolve
    for pattern in self.url_patterns:
  File "C:\Python27\lib\site-packages\django\core\urlresolvers.py", line 402, in url_patterns
    patterns = getattr(self.urlconf_module, "urlpatterns", self.urlconf_module)
  File "C:\Python27\lib\site-packages\django\core\urlresolvers.py", line 396, in urlconf_module
    self._urlconf_module = import_module(self.urlconf_name)
  File "C:\Python27\Lib\importlib\__init__.py", line 37, in import_module
    __import__(name)
  File "C:\Users\Administrator\PycharmProjects\blog\blog\urls.py", line 12, in <module>
    url(r'^', include('myblog.urls')),
  File "C:\Python27\lib\site-packages\django\conf\urls\__init__.py", line 33, in include
    urlconf_module = import_module(urlconf_module)
  File "C:\Python27\Lib\importlib\__init__.py", line 37, in import_module
    __import__(name)
  File "C:\Users\Administrator\PycharmProjects\blog\myblog\urls.py", line 16, in <module>
    url(r'^tag/$',views.tag,name='tag'),
AttributeError: 'module' object has no attribute 'tag'
2016-08-26 19:03:22,184 [Thread-3:6524] [django.request:256] [base:handle_uncaught_exception] [ERROR]- Internal Server Error: /
Traceback (most recent call last):
  File "C:\Python27\lib\site-packages\django\core\handlers\base.py", line 119, in get_response
    resolver_match = resolver.resolve(request.path_info)
  File "C:\Python27\lib\site-packages\django\core\urlresolvers.py", line 366, in resolve
    for pattern in self.url_patterns:
  File "C:\Python27\lib\site-packages\django\core\urlresolvers.py", line 402, in url_patterns
    patterns = getattr(self.urlconf_module, "urlpatterns", self.urlconf_module)
  File "C:\Python27\lib\site-packages\django\core\urlresolvers.py", line 396, in urlconf_module
    self._urlconf_module = import_module(self.urlconf_name)
  File "C:\Python27\Lib\importlib\__init__.py", line 37, in import_module
    __import__(name)
  File "C:\Users\Administrator\PycharmProjects\blog\blog\urls.py", line 12, in <module>
    url(r'^', include('myblog.urls')),
  File "C:\Python27\lib\site-packages\django\conf\urls\__init__.py", line 33, in include
    urlconf_module = import_module(urlconf_module)
  File "C:\Python27\Lib\importlib\__init__.py", line 37, in import_module
    __import__(name)
  File "C:\Users\Administrator\PycharmProjects\blog\myblog\urls.py", line 16, in <module>
    url(r'^tag/$',views.tag,name='tag'),
AttributeError: 'module' object has no attribute 'tag'
2016-08-26 19:04:59,016 [Thread-2:1952] [django.request:256] [base:handle_uncaught_exception] [ERROR]- Internal Server Error: /
Traceback (most recent call last):
  File "C:\Python27\lib\site-packages\django\core\handlers\base.py", line 119, in get_response
    resolver_match = resolver.resolve(request.path_info)
  File "C:\Python27\lib\site-packages\django\core\urlresolvers.py", line 366, in resolve
    for pattern in self.url_patterns:
  File "C:\Python27\lib\site-packages\django\core\urlresolvers.py", line 402, in url_patterns
    patterns = getattr(self.urlconf_module, "urlpatterns", self.urlconf_module)
  File "C:\Python27\lib\site-packages\django\core\urlresolvers.py", line 396, in urlconf_module
    self._urlconf_module = import_module(self.urlconf_name)
  File "C:\Python27\Lib\importlib\__init__.py", line 37, in import_module
    __import__(name)
  File "C:\Users\Administrator\PycharmProjects\blog\blog\urls.py", line 12, in <module>
    url(r'^', include('myblog.urls')),
  File "C:\Python27\lib\site-packages\django\conf\urls\__init__.py", line 33, in include
    urlconf_module = import_module(urlconf_module)
  File "C:\Python27\Lib\importlib\__init__.py", line 37, in import_module
    __import__(name)
  File "C:\Users\Administrator\PycharmProjects\blog\myblog\urls.py", line 2, in <module>
    from myblog import views
  File "C:\Users\Administrator\PycharmProjects\blog\myblog\views.py", line 221
    return render(request, 'tag_archive.html', locals())
SyntaxError: 'return' outside function
2016-08-27 00:51:13,085 [Thread-201:4300] [django.request:170] [base:get_response] [WARNING]- Not Found: /category/www.sina.com
2016-08-27 00:51:41,052 [Thread-203:4952] [django.request:170] [base:get_response] [WARNING]- Not Found: /category/www.sina.com
2016-08-27 10:40:46,361 [Thread-2:2468] [django.request:256] [base:handle_uncaught_exception] [ERROR]- Internal Server Error: /
Traceback (most recent call last):
  File "C:\Python27\lib\site-packages\django\core\handlers\base.py", line 132, in get_response
    response = wrapped_callback(request, *callback_args, **callback_kwargs)
  File "C:\Users\Administrator\PycharmProjects\blog\myblog\views.py", line 69, in index
    return render(request, 'index.html',locals())
  File "C:\Python27\lib\site-packages\django\shortcuts.py", line 67, in render
    template_name, context, request=request, using=using)
  File "C:\Python27\lib\site-packages\django\template\loader.py", line 99, in render_to_string
    return template.render(context, request)
  File "C:\Python27\lib\site-packages\django\template\backends\django.py", line 74, in render
    return self.template.render(context)
  File "C:\Python27\lib\site-packages\django\template\base.py", line 209, in render
    return self._render(context)
  File "C:\Python27\lib\site-packages\django\template\base.py", line 201, in _render
    return self.nodelist.render(context)
  File "C:\Python27\lib\site-packages\django\template\base.py", line 903, in render
    bit = self.render_node(node, context)
  File "C:\Python27\lib\site-packages\django\template\debug.py", line 79, in render_node
    return node.render(context)
  File "C:\Python27\lib\site-packages\django\template\loader_tags.py", line 135, in render
    return compiled_parent._render(context)
  File "C:\Python27\lib\site-packages\django\template\base.py", line 201, in _render
    return self.nodelist.render(context)
  File "C:\Python27\lib\site-packages\django\template\base.py", line 903, in render
    bit = self.render_node(node, context)
  File "C:\Python27\lib\site-packages\django\template\debug.py", line 79, in render_node
    return node.render(context)
  File "C:\Python27\lib\site-packages\django\template\loader_tags.py", line 65, in render
    result = block.nodelist.render(context)
  File "C:\Python27\lib\site-packages\django\template\base.py", line 903, in render
    bit = self.render_node(node, context)
  File "C:\Python27\lib\site-packages\django\template\debug.py", line 79, in render_node
    return node.render(context)
  File "C:\Python27\lib\site-packages\django\template\loader_tags.py", line 151, in render
    template = context.template.engine.get_template(template)
  File "C:\Python27\lib\site-packages\django\template\engine.py", line 167, in get_template
    template, origin = self.find_template(template_name, dirs)
  File "C:\Python27\lib\site-packages\django\template\engine.py", line 141, in find_template
    source, display_name = loader(name, dirs)
  File "C:\Python27\lib\site-packages\django\template\loaders\base.py", line 13, in __call__
    return self.load_template(template_name, template_dirs)
  File "C:\Python27\lib\site-packages\django\template\loaders\base.py", line 23, in load_template
    template = Template(source, origin, template_name, self.engine)
  File "C:\Python27\lib\site-packages\django\template\base.py", line 190, in __init__
    self.nodelist = engine.compile_string(template_string, origin)
  File "C:\Python27\lib\site-packages\django\template\engine.py", line 261, in compile_string
    return parser.parse()
  File "C:\Python27\lib\site-packages\django\template\base.py", line 341, in parse
    compiled_result = compile_func(self, token)
  File "C:\Python27\lib\site-packages\django\template\defaulttags.py", line 1155, in load
    lib = get_library(taglib)
  File "C:\Python27\lib\site-packages\django\template\base.py", line 1392, in get_library
    lib = import_library(taglib_module)
  File "C:\Python27\lib\site-packages\django\template\base.py", line 1331, in import_library
    mod = import_module(taglib_module)
  File "C:\Python27\Lib\importlib\__init__.py", line 37, in import_module
    __import__(name)
  File "C:\Users\Administrator\PycharmProjects\blog\myblog\templatetags\myfilter.py", line 9, in <module>
    registr.filter('month_to_upper', month_to_upper)
NameError: name 'registr' is not defined
2016-08-27 10:41:23,838 [Thread-6:10472] [django.request:256] [base:handle_uncaught_exception] [ERROR]- Internal Server Error: /
Traceback (most recent call last):
  File "C:\Python27\lib\site-packages\django\core\handlers\base.py", line 132, in get_response
    response = wrapped_callback(request, *callback_args, **callback_kwargs)
  File "C:\Users\Administrator\PycharmProjects\blog\myblog\views.py", line 69, in index
    return render(request, 'index.html',locals())
  File "C:\Python27\lib\site-packages\django\shortcuts.py", line 67, in render
    template_name, context, request=request, using=using)
  File "C:\Python27\lib\site-packages\django\template\loader.py", line 99, in render_to_string
    return template.render(context, request)
  File "C:\Python27\lib\site-packages\django\template\backends\django.py", line 74, in render
    return self.template.render(context)
  File "C:\Python27\lib\site-packages\django\template\base.py", line 209, in render
    return self._render(context)
  File "C:\Python27\lib\site-packages\django\template\base.py", line 201, in _render
    return self.nodelist.render(context)
  File "C:\Python27\lib\site-packages\django\template\base.py", line 903, in render
    bit = self.render_node(node, context)
  File "C:\Python27\lib\site-packages\django\template\debug.py", line 79, in render_node
    return node.render(context)
  File "C:\Python27\lib\site-packages\django\template\loader_tags.py", line 135, in render
    return compiled_parent._render(context)
  File "C:\Python27\lib\site-packages\django\template\base.py", line 201, in _render
    return self.nodelist.render(context)
  File "C:\Python27\lib\site-packages\django\template\base.py", line 903, in render
    bit = self.render_node(node, context)
  File "C:\Python27\lib\site-packages\django\template\debug.py", line 79, in render_node
    return node.render(context)
  File "C:\Python27\lib\site-packages\django\template\loader_tags.py", line 65, in render
    result = block.nodelist.render(context)
  File "C:\Python27\lib\site-packages\django\template\base.py", line 903, in render
    bit = self.render_node(node, context)
  File "C:\Python27\lib\site-packages\django\template\debug.py", line 79, in render_node
    return node.render(context)
  File "C:\Python27\lib\site-packages\django\template\loader_tags.py", line 151, in render
    template = context.template.engine.get_template(template)
  File "C:\Python27\lib\site-packages\django\template\engine.py", line 167, in get_template
    template, origin = self.find_template(template_name, dirs)
  File "C:\Python27\lib\site-packages\django\template\engine.py", line 141, in find_template
    source, display_name = loader(name, dirs)
  File "C:\Python27\lib\site-packages\django\template\loaders\base.py", line 13, in __call__
    return self.load_template(template_name, template_dirs)
  File "C:\Python27\lib\site-packages\django\template\loaders\base.py", line 23, in load_template
    template = Template(source, origin, template_name, self.engine)
  File "C:\Python27\lib\site-packages\django\template\base.py", line 190, in __init__
    self.nodelist = engine.compile_string(template_string, origin)
  File "C:\Python27\lib\site-packages\django\template\engine.py", line 261, in compile_string
    return parser.parse()
  File "C:\Python27\lib\site-packages\django\template\base.py", line 341, in parse
    compiled_result = compile_func(self, token)
  File "C:\Python27\lib\site-packages\django\template\defaulttags.py", line 868, in do_for
    nodelist_loop = parser.parse(('empty', 'endfor',))
  File "C:\Python27\lib\site-packages\django\template\base.py", line 317, in parse
    filter_expression = self.compile_filter(token.contents)
  File "C:\Python27\lib\site-packages\django\template\base.py", line 423, in compile_filter
    return FilterExpression(token, self)
  File "C:\Python27\lib\site-packages\django\template\base.py", line 633, in __init__
    filter_func = parser.find_filter(filter_name)
  File "C:\Python27\lib\site-packages\django\template\base.py", line 429, in find_filter
    raise TemplateSyntaxError("Invalid filter: '%s'" % filter_name)
TemplateSyntaxError: Invalid filter: 'get_index'
2016-08-28 10:41:37,595 [Thread-25:6208] [django.request:170] [base:get_response] [WARNING]- Not Found: /favicon.ico
2016-08-28 10:41:37,608 [Thread-26:2820] [django.request:170] [base:get_response] [WARNING]- Not Found: /favicon.ico
2016-08-28 17:11:23,688 [Thread-49:1560] [django.request:170] [base:get_response] [WARNING]- Not Found: /favicon.ico
2016-08-28 17:11:28,355 [Thread-58:9112] [django.request:170] [base:get_response] [WARNING]- Not Found: /favicon.ico
2016-08-28 17:11:32,868 [Thread-61:2584] [django.request:170] [base:get_response] [WARNING]- Not Found: /favicon.ico
2016-08-28 19:15:31,194 [Thread-7:2772] [django.request:256] [base:handle_uncaught_exception] [ERROR]- Internal Server Error: /article/
Traceback (most recent call last):
  File "C:\Python27\lib\site-packages\django\core\handlers\base.py", line 132, in get_response
    response = wrapped_callback(request, *callback_args, **callback_kwargs)
  File "C:\Users\Administrator\PycharmProjects\blog\myblog\views.py", line 114, in article
    return render(request,'article.html',locals())
  File "C:\Python27\lib\site-packages\django\shortcuts.py", line 67, in render
    template_name, context, request=request, using=using)
  File "C:\Python27\lib\site-packages\django\template\loader.py", line 99, in render_to_string
    return template.render(context, request)
  File "C:\Python27\lib\site-packages\django\template\backends\django.py", line 74, in render
    return self.template.render(context)
  File "C:\Python27\lib\site-packages\django\template\base.py", line 209, in render
    return self._render(context)
  File "C:\Python27\lib\site-packages\django\template\base.py", line 201, in _render
    return self.nodelist.render(context)
  File "C:\Python27\lib\site-packages\django\template\base.py", line 903, in render
    bit = self.render_node(node, context)
  File "C:\Python27\lib\site-packages\django\template\debug.py", line 79, in render_node
    return node.render(context)
  File "C:\Python27\lib\site-packages\django\template\loader_tags.py", line 113, in render
    compiled_parent = self.get_parent(context)
  File "C:\Python27\lib\site-packages\django\template\loader_tags.py", line 110, in get_parent
    return context.template.engine.get_template(parent)
  File "C:\Python27\lib\site-packages\django\template\engine.py", line 167, in get_template
    template, origin = self.find_template(template_name, dirs)
  File "C:\Python27\lib\site-packages\django\template\engine.py", line 141, in find_template
    source, display_name = loader(name, dirs)
  File "C:\Python27\lib\site-packages\django\template\loaders\base.py", line 13, in __call__
    return self.load_template(template_name, template_dirs)
  File "C:\Python27\lib\site-packages\django\template\loaders\base.py", line 23, in load_template
    template = Template(source, origin, template_name, self.engine)
  File "C:\Python27\lib\site-packages\django\template\base.py", line 190, in __init__
    self.nodelist = engine.compile_string(template_string, origin)
  File "C:\Python27\lib\site-packages\django\template\engine.py", line 261, in compile_string
    return parser.parse()
  File "C:\Python27\lib\site-packages\django\template\base.py", line 341, in parse
    compiled_result = compile_func(self, token)
  File "C:\Python27\lib\site-packages\django\template\defaulttags.py", line 868, in do_for
    nodelist_loop = parser.parse(('empty', 'endfor',))
  File "C:\Python27\lib\site-packages\django\template\base.py", line 339, in parse
    self.invalid_block_tag(token, command, parse_until)
  File "C:\Python27\lib\site-packages\django\template\base.py", line 394, in invalid_block_tag
    (command, get_text_list(["'%s'" % p for p in parse_until])))
TemplateSyntaxError: Invalid block tag: 'article', expected 'empty' or 'endfor'
2016-08-28 19:23:04,026 [Thread-8:9424] [django.request:256] [base:handle_uncaught_exception] [ERROR]- Internal Server Error: /article/
Traceback (most recent call last):
  File "C:\Python27\lib\site-packages\django\core\handlers\base.py", line 132, in get_response
    response = wrapped_callback(request, *callback_args, **callback_kwargs)
  File "C:\Users\Administrator\PycharmProjects\blog\myblog\views.py", line 114, in article
    return render(request,'article.html',locals())
  File "C:\Python27\lib\site-packages\django\shortcuts.py", line 67, in render
    template_name, context, request=request, using=using)
  File "C:\Python27\lib\site-packages\django\template\loader.py", line 99, in render_to_string
    return template.render(context, request)
  File "C:\Python27\lib\site-packages\django\template\backends\django.py", line 74, in render
    return self.template.render(context)
  File "C:\Python27\lib\site-packages\django\template\base.py", line 209, in render
    return self._render(context)
  File "C:\Python27\lib\site-packages\django\template\base.py", line 201, in _render
    return self.nodelist.render(context)
  File "C:\Python27\lib\site-packages\django\template\base.py", line 903, in render
    bit = self.render_node(node, context)
  File "C:\Python27\lib\site-packages\django\template\debug.py", line 79, in render_node
    return node.render(context)
  File "C:\Python27\lib\site-packages\django\template\loader_tags.py", line 113, in render
    compiled_parent = self.get_parent(context)
  File "C:\Python27\lib\site-packages\django\template\loader_tags.py", line 110, in get_parent
    return context.template.engine.get_template(parent)
  File "C:\Python27\lib\site-packages\django\template\engine.py", line 167, in get_template
    template, origin = self.find_template(template_name, dirs)
  File "C:\Python27\lib\site-packages\django\template\engine.py", line 141, in find_template
    source, display_name = loader(name, dirs)
  File "C:\Python27\lib\site-packages\django\template\loaders\base.py", line 13, in __call__
    return self.load_template(template_name, template_dirs)
  File "C:\Python27\lib\site-packages\django\template\loaders\base.py", line 23, in load_template
    template = Template(source, origin, template_name, self.engine)
  File "C:\Python27\lib\site-packages\django\template\base.py", line 190, in __init__
    self.nodelist = engine.compile_string(template_string, origin)
  File "C:\Python27\lib\site-packages\django\template\engine.py", line 261, in compile_string
    return parser.parse()
  File "C:\Python27\lib\site-packages\django\template\base.py", line 341, in parse
    compiled_result = compile_func(self, token)
  File "C:\Python27\lib\site-packages\django\template\defaulttags.py", line 868, in do_for
    nodelist_loop = parser.parse(('empty', 'endfor',))
  File "C:\Python27\lib\site-packages\django\template\base.py", line 339, in parse
    self.invalid_block_tag(token, command, parse_until)
  File "C:\Python27\lib\site-packages\django\template\base.py", line 394, in invalid_block_tag
    (command, get_text_list(["'%s'" % p for p in parse_until])))
TemplateSyntaxError: Invalid block tag: 'article', expected 'empty' or 'endfor'
2016-08-28 19:23:52,910 [Thread-9:9852] [django.request:256] [base:handle_uncaught_exception] [ERROR]- Internal Server Error: /article/
Traceback (most recent call last):
  File "C:\Python27\lib\site-packages\django\core\handlers\base.py", line 132, in get_response
    response = wrapped_callback(request, *callback_args, **callback_kwargs)
  File "C:\Users\Administrator\PycharmProjects\blog\myblog\views.py", line 114, in article
    return render(request,'article.html',locals())
  File "C:\Python27\lib\site-packages\django\shortcuts.py", line 67, in render
    template_name, context, request=request, using=using)
  File "C:\Python27\lib\site-packages\django\template\loader.py", line 99, in render_to_string
    return template.render(context, request)
  File "C:\Python27\lib\site-packages\django\template\backends\django.py", line 74, in render
    return self.template.render(context)
  File "C:\Python27\lib\site-packages\django\template\base.py", line 209, in render
    return self._render(context)
  File "C:\Python27\lib\site-packages\django\template\base.py", line 201, in _render
    return self.nodelist.render(context)
  File "C:\Python27\lib\site-packages\django\template\base.py", line 903, in render
    bit = self.render_node(node, context)
  File "C:\Python27\lib\site-packages\django\template\debug.py", line 79, in render_node
    return node.render(context)
  File "C:\Python27\lib\site-packages\django\template\loader_tags.py", line 113, in render
    compiled_parent = self.get_parent(context)
  File "C:\Python27\lib\site-packages\django\template\loader_tags.py", line 110, in get_parent
    return context.template.engine.get_template(parent)
  File "C:\Python27\lib\site-packages\django\template\engine.py", line 167, in get_template
    template, origin = self.find_template(template_name, dirs)
  File "C:\Python27\lib\site-packages\django\template\engine.py", line 141, in find_template
    source, display_name = loader(name, dirs)
  File "C:\Python27\lib\site-packages\django\template\loaders\base.py", line 13, in __call__
    return self.load_template(template_name, template_dirs)
  File "C:\Python27\lib\site-packages\django\template\loaders\base.py", line 23, in load_template
    template = Template(source, origin, template_name, self.engine)
  File "C:\Python27\lib\site-packages\django\template\base.py", line 190, in __init__
    self.nodelist = engine.compile_string(template_string, origin)
  File "C:\Python27\lib\site-packages\django\template\engine.py", line 261, in compile_string
    return parser.parse()
  File "C:\Python27\lib\site-packages\django\template\base.py", line 341, in parse
    compiled_result = compile_func(self, token)
  File "C:\Python27\lib\site-packages\django\template\defaulttags.py", line 868, in do_for
    nodelist_loop = parser.parse(('empty', 'endfor',))
  File "C:\Python27\lib\site-packages\django\template\base.py", line 339, in parse
    self.invalid_block_tag(token, command, parse_until)
  File "C:\Python27\lib\site-packages\django\template\base.py", line 394, in invalid_block_tag
    (command, get_text_list(["'%s'" % p for p in parse_until])))
TemplateSyntaxError: Invalid block tag: 'article', expected 'empty' or 'endfor'
2016-08-28 19:23:55,176 [Thread-10:6456] [django.request:256] [base:handle_uncaught_exception] [ERROR]- Internal Server Error: /article/
Traceback (most recent call last):
  File "C:\Python27\lib\site-packages\django\core\handlers\base.py", line 132, in get_response
    response = wrapped_callback(request, *callback_args, **callback_kwargs)
  File "C:\Users\Administrator\PycharmProjects\blog\myblog\views.py", line 114, in article
    return render(request,'article.html',locals())
  File "C:\Python27\lib\site-packages\django\shortcuts.py", line 67, in render
    template_name, context, request=request, using=using)
  File "C:\Python27\lib\site-packages\django\template\loader.py", line 99, in render_to_string
    return template.render(context, request)
  File "C:\Python27\lib\site-packages\django\template\backends\django.py", line 74, in render
    return self.template.render(context)
  File "C:\Python27\lib\site-packages\django\template\base.py", line 209, in render
    return self._render(context)
  File "C:\Python27\lib\site-packages\django\template\base.py", line 201, in _render
    return self.nodelist.render(context)
  File "C:\Python27\lib\site-packages\django\template\base.py", line 903, in render
    bit = self.render_node(node, context)
  File "C:\Python27\lib\site-packages\django\template\debug.py", line 79, in render_node
    return node.render(context)
  File "C:\Python27\lib\site-packages\django\template\loader_tags.py", line 113, in render
    compiled_parent = self.get_parent(context)
  File "C:\Python27\lib\site-packages\django\template\loader_tags.py", line 110, in get_parent
    return context.template.engine.get_template(parent)
  File "C:\Python27\lib\site-packages\django\template\engine.py", line 167, in get_template
    template, origin = self.find_template(template_name, dirs)
  File "C:\Python27\lib\site-packages\django\template\engine.py", line 141, in find_template
    source, display_name = loader(name, dirs)
  File "C:\Python27\lib\site-packages\django\template\loaders\base.py", line 13, in __call__
    return self.load_template(template_name, template_dirs)
  File "C:\Python27\lib\site-packages\django\template\loaders\base.py", line 23, in load_template
    template = Template(source, origin, template_name, self.engine)
  File "C:\Python27\lib\site-packages\django\template\base.py", line 190, in __init__
    self.nodelist = engine.compile_string(template_string, origin)
  File "C:\Python27\lib\site-packages\django\template\engine.py", line 261, in compile_string
    return parser.parse()
  File "C:\Python27\lib\site-packages\django\template\base.py", line 341, in parse
    compiled_result = compile_func(self, token)
  File "C:\Python27\lib\site-packages\django\template\defaulttags.py", line 868, in do_for
    nodelist_loop = parser.parse(('empty', 'endfor',))
  File "C:\Python27\lib\site-packages\django\template\base.py", line 339, in parse
    self.invalid_block_tag(token, command, parse_until)
  File "C:\Python27\lib\site-packages\django\template\base.py", line 394, in invalid_block_tag
    (command, get_text_list(["'%s'" % p for p in parse_until])))
TemplateSyntaxError: Invalid block tag: 'article', expected 'empty' or 'endfor'
